Workbook
Name AGREGADOSECOMPONENTES1COLABORADOR: [1]GERAL!$G$22
Name CANAL1COLABORADOR: [1]GERAL!$G$14
Name CANAL2COLABORADORES: [1]GERAL!$G$15
Name COLADEIRA1COLABORADOR: [1]GERAL!$G$9
Name COLADEIRA2COLABORADORES: [1]GERAL!$G$10
Name COLAGEMMANUAL1COLABORADOR: [1]GERAL!$G$11
Name EMBALAGEM1COLOBORADOR: [1]GERAL!$G$31
Name EMBALAGEM2COLABORADORES: [1]GERAL!$G$30
Name F2001COLABORADOR: [1]GERAL!$G$18
Name F2002COLABORADORES: [1]GERAL!$G$19
Name HETTICH1COLABORADOR: [1]GERAL!$G$20
Name HETTICH2COLABORADORES: [1]GERAL!$G$21
Name LIMPEZAESEPARACAO1COLABORADOR: [1]GERAL!$G$13
Name LIMPEZAESEPARACAO2COLABORADORES: [1]GERAL!$G$12
Name MONTAGEMDUPLAMEIOPROFISSIONALAJUDANTE: [1]GERAL!$G$26
Name MONTAGEMDUPLAPROFISSIONALAJUDANTE: [1]GERAL!$G$25
Name MONTAGEMEASSISTENCIAPROFISSIONAL: [1]GERAL!$G$35
Name MONTAGEMEASSISTENCIAPROFISSIONALMEIOOFICIAL: [1]GERAL!$G$33
Name MONTAGEMEASSISTENCIAPROFISSIONALPROFISSIONAL: [1]GERAL!$G$32
Name MONTAGEMEASSSISTENCIAPROFISSIONALAJUDANTE: [1]GERAL!$G$34
Name MONTAGEMEQUIPE3COLABORES: [1]GERAL!$G$23
Name MONTAGEMINDIVIDUALMEIOOFICIAL: [1]GERAL!$G$28
Name SECCIONADORA1COLABORADOR: [1]GERAL!$G$4
Name SECCIONADORA2COLABORADORES: [1]GERAL!$G$3
Name SEPARACAOECONFERENCIA1COLABORADOR: [1]GERAL!$G$6
Name SEPARACAOECONFERENCIA2COLABORADORES: [1]GERAL!$G$5
Name UNIAOEENGROSSO1COLABORADOR: [1]GERAL!$G$8
Name UNIAOEENGROSSO2COLABORADORES: [1]GERAL!$G$7
Name USINAGEM1COLABORADOR: [1]GERAL!$G$17
Name USINAGEM2COLABORADORES: [1]GERAL!$G$16

Sheet CADASTRO CLIENTE
C2: CADASTRO DO CLIENTE
D3: ATUALIZAÇÃO DA PLANILHA: | E3: 10.01.20
D4: VERSÃO: | E4: V1
A5: DATA: | C5: 10.01.20
A6: CLIENTE:
A7: EMPREENDIMENTO:
A8: AMBIENTE:
A9: PRODUTO:

Sheet MATERIAIS
F1: DATA: | G1: 45613
B2: LEVANTAMENTO DE MATERIAIS | F2: CLIENTE: | G2: ='CADASTRO CLIENTE'!C6 -> 0
F3: EMPREENDIMENTO: | G3: ='CADASTRO CLIENTE'!C7 -> 0
B4: ATUALIZAÇÃO DA PLANILHA: | C4: ='CADASTRO CLIENTE'!E3 -> 10.01.20 | F4: AMBIENTE: | G4: ='CADASTRO CLIENTE'!C8 -> 0
F5: PRODUTO: | G5: ='CADASTRO CLIENTE'!C9 -> 0
B6: PRODUTO / MATERIAL | C6: UNIDADE | D6: CUSTO FINAL DOS MATERIAIS | E6: QUANTIDADE | F6: CUSTO X QUANTIDADE | G6: % POR CATEGORIA | H6: % GLOBAL
A7: TOTAL | F7: =F8+F25+F42+F91+F109+F167+F171+F177+F194+F205 -> 0 | H7: 1
A8: CHAPAS DE MDF | F8: =F9+F15 -> 0 | G8: 1 | H8: =F8*$H$7/$F$7 -> #DIV/0!
B9: BRANCO - MDF | F9: =SUM(F10:F14) -> 0 | G9: =F9*$G$8/$F$8 -> #DIV/0! | H9: =F9*$H$7/$F$7 -> #DIV/0!
B10: MDF Branco Tx 06mm | C10: CHAPA | D10: 164 | F10: =D10*E10 -> 0 | G10: =F10*$G$8/$F$8 -> #DIV/0! | H10: =F10*$H$7/$F$7 -> #DIV/0! | XDI10: =SUM(E10:XDH10) -> #DIV/0!
B11: MDF Branco TX 15mm | C11: CHAPA | D11: 220 | F11: =D11*E11 -> 0 | G11: =F11*$G$8/$F$8 -> #DIV/0! | H11: =F11*$H$7/$F$7 -> #DIV/0! | XDI11: =SUM(E11:XDH11) -> #DIV/0!
B12: MDF Branco Tx 18mm | C12: CHAPA | D12: 0 | E12: 0 | F12: =D12*E12 -> 0 | G12: =F12*$G$8/$F$8 -> #DIV/0! | H12: =F12*$H$7/$F$7 -> #DIV/0! | XDI12: =SUM(E12:XDH12) -> #DIV/0!
B13: MDF Branco 15 mm NAVAL | C13: CHAPA | D13: 320 | F13: =D13*E13 -> 0 | G13: =F13*$G$8/$F$8 -> #DIV/0! | H13: =F13*$H$7/$F$7 -> #DIV/0! | XDI13: =SUM(E13:XDH13) -> #DIV/0!
B15: UNICOLORES e AMADEIRADO - MDF | F15: =SUM(F16:F23) -> 0 | G15: =F15*$G$8/$F$8 -> #DIV/0! | H15: =F15*$H$7/$F$7 -> #DIV/0!
B16: MDF Unicolor TX 06mm | C16: CHAPA | D16: 250 | E16: 0 | F16: =D16*E16 -> 0 | G16: =F16*$G$8/$F$8 -> #DIV/0! | H16: =F16*$H$7/$F$7 -> #DIV/0!
B17: MDF Unicolor TX 15mm | C17: CHAPA | D17: 400 | F17: =D17*E17 -> 0 | G17: =F17*$G$8/$F$8 -> #DIV/0! | H17: =F17*$H$7/$F$7 -> #DIV/0!
B18: MDF Unicolor Tx 18mm | C18: CHAPA | D18: 0 | F18: =D18*E18 -> 0 | G18: =F18*$G$8/$F$8 -> #DIV/0! | H18: =F18*$H$7/$F$7 -> #DIV/0!
B19: MDF Amadeirado 06mm | C19: CHAPA | D19: 250 | F19: =D19*E19 -> 0 | G19: =F19*$G$8/$F$8 -> #DIV/0! | H19: =F19*$H$7/$F$7 -> #DIV/0!
B20: MDF Amadeirado 15mm | C20: CHAPA | D20: 400 | F20: =D20*E20 -> 0 | G20: =F20*$G$8/$F$8 -> #DIV/0! | H20: =F20*$H$7/$F$7 -> #DIV/0!
B21: MDF Amadeirado 18mm | C21: CHAPA | D21: 0 | E21: 0 | F21: =D21*E21 -> 0 | G21: =F21*$G$8/$F$8 -> #DIV/0! | H21: =F21*$H$7/$F$7 -> #DIV/0!
B22: MDF Amadeirado 25mm | C22: CHAPA | D22: 0 | E22: 0 | F22: =D22*E22 -> 0 | G22: =F22*$G$8/$F$8 -> #DIV/0! | H22: =F22*$H$7/$F$7 -> #DIV/0!
A25: FITA DE BORDA | F25: =F26+F34 -> 0 | G25: 1 | H25: =F25*$H$7/$F$7 -> #DIV/0!
B26: BRANCA - FITA DE BORDA 0,45mm | F26: =SUM(F27:F33) -> 0 | G26: =F26*$G$25/$F$25 -> #DIV/0! | H26: =F26*$H$7/$F$7 -> #DIV/0!
B27: Fita de Borda Branco Tx 22mm(Metros) - 0,45mm | C27: METRO | D27: 30 | E27: 0 | F27: =D27*E27 -> 0 | G27: =F27*$G$25/$F$25 -> #DIV/0! | H27: =F27*$H$7/$F$7 -> #DIV/0!
B28: Fita de Borda Branco Tx 29mm (Metros) - 0,45mm | C28: METRO | D28: 0 | E28: 0 | F28: =D28*E28 -> 0 | G28: =F28*$G$25/$F$25 -> #DIV/0! | H28: =F28*$H$7/$F$7 -> #DIV/0!
B29: Fita de Borda Branco Tx 35mm (Metros) - 0,45mm | C29: METRO | D29: 0 | E29: 0 | F29: =D29*E29 -> 0 | G29: =F29*$G$25/$F$25 -> #DIV/0! | H29: =F29*$H$7/$F$7 -> #DIV/0!
B31: Fita de Borda Branco Tx 22 (Metros) - 1,00mm | C31: METRO | D31: 0 | E31: 0 | F31: =D31*E31 -> 0 | G31: =F31*$G$25/$F$25 -> #DIV/0! | H31: =F31*$H$7/$F$7 -> #DIV/0!
B32: Fita de Borda Branco Tx 35 (Metros) - 1,00mm | C32: METRO | D32: 0 | E32: 0 | F32: =D32*E32 -> 0 | G32: =F32*$G$25/$F$25 -> #DIV/0! | H32: =F32*$H$7/$F$7 -> #DIV/0!
B34: AMADEIRADO - FITA DE BORDA 1,00mm | F34: =SUM(F35:F41) -> 0 | G34: =F34*$G$25/$F$25 -> #DIV/0! | H34: =F34*$H$7/$F$7 -> #DIV/0!
B35: Fita de Borda Amadeirado 22mm (Rolo) - 0,45mm | C35: ROLO 50M | D35: 80 | F35: =D35*E35 -> 0 | G35: =F35*$G$25/$F$25 -> #DIV/0! | H35: =F35*$H$7/$F$7 -> #DIV/0!
B36: Fita de Borda Amadeirado 40mm (Rolo) - 0,45mm | C36: ROLO 20M | D36: 54 | F36: =D36*E36 -> 0 | G36: =F36*$G$25/$F$25 -> #DIV/0! | H36: =F36*$H$7/$F$7 -> #DIV/0!
B37: Fita de Borda Amadeirado 64mm (Rolo) - 0,45mm | C37: ROLO 25M | D37: 94 | E37: 0 | F37: =D37*E37 -> 0 | G37: =F37*$G$25/$F$25 -> #DIV/0! | H37: =F37*$H$7/$F$7 -> #DIV/0!
B39: Fita de Borda Amadeirado Tx 22 (ROLO - 25 METROS) - 1,00 mm | C39: ROLO 25M | D39: 0 | E39: 0 | F39: =D39*E39 -> 0 | G39: =F39*$G$25/$F$25 -> #DIV/0! | H39: =F39*$H$7/$F$7 -> #DIV/0!
B40: Fita de Borda Amadeirado Tx 35 (ROLO - 25 METROS) - 1,00 mm | C40: ROLO 25M | D40: 0 | E40: 0 | F40: =D40*E40 -> 0 | G40: =F40*$G$25/$F$25 -> #DIV/0! | H40: =F40*$H$7/$F$7 -> #DIV/0!
A42: ACESSÓRIOS | F42: =F43+F52+F60+F68+F78 -> 0 | G42: 1 | H42: =F42*$H$7/$F$7 -> #DIV/0!
B43: Suportes | F43: =SUM(F44:F51) -> 0 | G43: =F43*$G$42/$F$42 -> #DIV/0! | H43: =F43*$H$7/$F$7 -> #DIV/0!
B44: VB (Pino + VB 19mm BRANCO/ PRETO) - DUPLO | C44: UNIDADE | D44: 0 | E44: 0 | F44: =D44*E44 -> 0 | G44: =F44*$G$42/$F$42 -> #DIV/0! | H44: =F44*$H$7/$F$7 -> #DIV/0!
B45: Pino Cromado | C45: UNIDADE | D45: 0 | E45: 0 | F45: =D45*E45 -> 0 | G45: =F45*$G$42/$F$42 -> #DIV/0! | H45: =F45*$H$7/$F$7 -> #DIV/0!
B46: Pino de Plástico | C46: UNIDADE | D46: 0 | E46: 0 | F46: =D46*E46 -> 0 | G46: =F46*$G$42/$F$42 -> #DIV/0! | H46: =F46*$H$7/$F$7 -> #DIV/0!
B47: Cantoneira Cromada 2 Furos | C47: UNIDADE | D47: 0.25 | E47: 0 | F47: =D47*E47 -> 0 | G47: =F47*$G$42/$F$42 -> #DIV/0! | H47: =F47*$H$7/$F$7 -> #DIV/0!
...

Sheet PRODUÇÃO E MONTAGEM
B1: LEVANTAMENTO DE MATERIAIS | F1: DATA: | G1: ='CADASTRO CLIENTE'!C5 -> 10.01.20
F2: CLIENTE: | G2: ='CADASTRO CLIENTE'!C6 -> 0
B3: ATUALIZAÇÃO DA PLANILHA: | C3: ='CADASTRO CLIENTE'!E3 -> 10.01.20 | F3: EMPREENDIMENTO: | G3: ='CADASTRO CLIENTE'!C7 -> 0
B4: CUSTO FIXO - ESTIMADO | C4: 7200 | F4: AMBIENTE: | G4: ='CADASTRO CLIENTE'!C8 -> 0
B5: CONSIDERAR Nº DE DIAS UTÉIS NO MÊS: | C5: 22 | D5: =C4/C5 -> 327.27273 | F5: PRODUTO: | G5: ='CADASTRO CLIENTE'!C9 -> 0
B7: PRODUTO / MATERIAL | C7: UNIDADE | D7: CUSTOS | E7: QUANTIDADE | F7: CUSTO X QUANTIDADE | G7: % POR CATEGORIA | H7: % GLOBAL
A8: TOTAL | F8: =F9+F14+F19+F31+F38 -> 0 | H8: 1
A9: AJUSTE DE PROJETO | F9: =SUM(F10:F13) -> 0 | G9: 1 | H9: =F9*$H$8/$F$8 -> #DIV/0!
B10: MEDIDAS IN LOCCO | C10: HORA | D10: 15 | E10: 0 | F10: =D10*E10 -> 0 | G10: =F10*$G$9/$F$9 -> #DIV/0! | H10: =F10*$H$8/$F$8 -> #DIV/0!
B11: AJUSTE DE PROJETO (MODELAGEM) | C11: HORAS | D11: 15 | E11: 0 | F11: =D11*E11 -> 0 | G11: =F11*$G$9/$F$9 -> #DIV/0! | H11: =F11*$H$8/$F$8 -> #DIV/0!
B12: AJUSTE DE PROJETO (PRODUÇÃO) | C12: HORAS | D12: 15 | E12: 0 | F12: =D12*E12 -> 0 | G12: =F12*$G$9/$F$9 -> #DIV/0! | H12: =F12*$H$8/$F$8 -> #DIV/0!
A14: CARREGAMENTO E ORGANIZAÇÃO | F14: =SUM(F15:F18) -> 0 | G14: 1 | H14: =F14*$H$8/$F$8 -> #DIV/0!
B15: CARREGAMENTO EMPRESA - EQUIPE DE ENTREGA | C15: HORAS | D15: 30 | E15: 0 | F15: =D15*E15 -> 0 | G15: =F15*G14/F14 -> #DIV/0! | H15: =F15*$H$8/$F$8 -> #DIV/0!
B16: DESCARGA CASA DO CLIENTE - EQUIPE DE ENTREGA | C16: HORAS | D16: 0 | E16: 0 | F16: =D16*E16 -> 0 | G16: =F16*G15/F15 -> #DIV/0! | H16: =F16*$H$8/$F$8 -> #DIV/0!
B17: DESCARGA/ORGANIZAÇÃO FERRAMENTAS EMPRESA - EQUIPE DEMONTAGEM | C17: HORAS | D17: 0 | E17: 0 | F17: =D17*E17 -> 0 | G17: =F17*G16/F16 -> #DIV/0! | H17: =F17*$H$8/$F$8 -> #DIV/0!
A19: PRODUÇÃO EMPRESA | F19: =SUM(F20:F30) -> 0 | G19: 1 | H19: =F19*$H$8/$F$8 -> #DIV/0!
B20: PRODUÇÃO EMPRESA - CUSTO TOTAL DA PRODUÇÃO - DIA | C20: DIAS | D20: 409 | F20: =D20*E20 -> 0 | G20: =F20*$G$19/F19 -> #DIV/0! | H20: =F20*$H$8/$F$8 -> #DIV/0!
B21: PRODUÇÃO EMPRESA - CUSTO TOTAL DA PRODUÇÃO - HORAS | C21: HORA | D21: 0 | E21: 0 | F21: =D21*E21 -> 0 | G21: =F21*$G$19/F19 -> #DIV/0! | H21: =F21*$H$8/$F$8 -> #DIV/0!
B23: PRODUÇÃO EMPRESA - CUSTO DA EQUIPE A - TRABALHO EM CÉLULAS | C23: DIAS | D23: 0 | E23: 0 | F23: =D23*E23 -> 0 | G23: =F23*$G$19/F19 -> #DIV/0! | H23: =F23*$H$8/$F$8 -> #DIV/0!
B24: PRODUÇÃO EMPRESA - CUSTO DA EQUIPE B - TRABALHO EM CÉLULAS | C24: DIAS | D24: 0 | E24: 0 | F24: =D24*E24 -> 0 | G24: =F24*G19/F19 -> #DIV/0! | H24: =F24*$H$8/$F$8 -> #DIV/0!
B25: PRODUÇÃO EMPRESA - CUSTO DA EQUIPE C - TRABALHO EM CÉLULAS | C25: DIAS | D25: 0 | E25: 0 | F25: =D25*E25 -> 0 | G25: =F25*G19/F19 -> #DIV/0! | H25: =F25*$H$8/$F$8 -> #DIV/0!
B27: PRODUÇÃO COMISSIONADA - MARCENEIRO A | C27: VALOR | D27: 0 | E27: 0 | F27: =D27*E27 -> 0 | G27: =F27*$G$19/F19 -> #DIV/0! | H27: =F27*$H$8/$F$8 -> #DIV/0!
B28: PRODUÇÃO COMISSIONADA - MARCENEIRO B | C28: VALOR | D28: 0 | E28: 0 | F28: =D28*E28 -> 0 | G28: =F28*$G$19/F19 -> #DIV/0! | H28: =F28*$H$8/$F$8 -> #DIV/0!
B29: PRODUÇÃO COMISSIONADA - MARCENEIRO C | C29: VALOR | D29: 0 | E29: 0 | F29: =D29*E29 -> 0 | G29: =F29*$G$19/F19 -> #DIV/0! | H29: =F29*$H$8/$F$8 -> #DIV/0!
A31: MONTAGEM CASA DO CLIENTE | F31: =SUM(F32:F37) -> 0 | G31: 1 | H31: =F31*$H$8/$F$8 -> #DIV/0!
B32: MONTAGEM CASA DO CLIENTE - EQUIPE A (JOSÉ LUIZ E LUCAS) | C32: DIAS | D32: 409 | E32: 0 | F32: =D32*E32 -> 0 | G32: =F32*G31/F31 -> #DIV/0! | H32: =F32*$H$8/$F$8 -> #DIV/0!
B33: MONTAGEM CASA DO CLIENTE - EQUIPE B | C33: DIAS | D33: 0 | E33: 0 | F33: =D33*E33 -> 0 | G33: =F33*$G$31/F31 -> #DIV/0! | H33: =F33*$H$8/$F$8 -> #DIV/0!
B34: MONTAGEM CASA DO CLIENTE - EQUIPE C | C34: DIAS | D34: 0 | E34: 0 | F34: =D34*E34 -> 0 | G34: =F34*$G$31/F31 -> #DIV/0! | H34: =F34*$H$8/$F$8 -> #DIV/0!
B36: EQUIPE DE LIMPEZA E ENTREGA | C36: DIAS | D36: 0 | E36: 0 | F36: =D36*E36 -> 0 | G36: =F36*$G$31/F31 -> #DIV/0! | H36: =F36*$H$8/$F$8 -> #DIV/0!
A38: REGULAGENS + ASSISTÊNCIA TÉCNICA | F38: =SUM(F39:F41) -> 0 | G38: 1 | H38: =F38*$H$8/$F$8 -> #DIV/0!
B39: REGULAGENS DE PORTAS (MÉDIA 1 HORA DE SERVIÇO) + DESLOCAMENTO (1 HORA) | C39: Nº DE VEZES | D39: 50 | E39: 0 | F39: =D39*E39 -> 0 | G39: =F39*$G$38/F38 -> #DIV/0! | H39: =F39*$H$8/$F$8 -> #DIV/0!
B40: ASSISTÊNCIA TÉCNICA (MÉDIA 1,5 HORA DE SERVIÇO) + DESLOCAMENTO (1 HORA) | C40: Nº DE VEZES | D40: 0 | E40: 0 | F40: =D40*E40 -> 0 | G40: =F40*$G$39/F39 -> #DIV/0! | H40: =F40*$H$8/$F$8 -> #DIV/0!

Sheet PREÇO DE VENDA
B1: PLANILHA DE FORMAÇÃO DE PREÇO DE VENDA | F1: PREÇO DE VENDA P/ ORÇAMENTO
C2: ATUALIZAÇÃO DA PLANILHA: | D2: ='CADASTRO CLIENTE'!E3 -> 10.01.20 | F2: FORMA DE PAGAMEN. | G2: VALOR | H2: PARCELA
B3: DATA: | C3: ='CADASTRO CLIENTE'!C5 -> 10.01.20 | F3: À VISTA | G3: =D54 -> 0 | H3: 50% + 50%
B4: CLIENTE: | C4: ='CADASTRO CLIENTE'!C6 -> 0 | F4: À PRAZO 10% | G4: =(G3)/0.885 -> 0
B5: EMPREENDIMENTO: | C5: ='CADASTRO CLIENTE'!C7 -> 0 | F5: 3X | G5: =D58 -> 0 | H5: =G58 -> 0
B6: AMBIENTE: | C6: ='CADASTRO CLIENTE'!C8 -> 0 | F6: 6X | G6: =D61 -> 0 | H6: =G61 -> 0
B7: PRODUTO: | C7: ='CADASTRO CLIENTE'!C9 -> 0 | F7: 8X | G7: =D63 -> 0 | H7: =G63 -> 0
A8: PARÂMETROS DA EMPRESA | F8: 10X | G8: =D65 -> 0 | H8: =G65 -> 0
A10: IMPOSTOS | B10: SUPER SIMPLES | C10: 0.04 | D10: =$C$31*C10 -> 0
A11: OUTROS | B11: COMISSÕES | C11: 0.03 | D11: =$C$31*C11 -> 0
B12: FRETE | C12: 0 | D12: =$C$31*C12 -> 0
B13: OUTROS | C13: 0.015 | D13: =$C$31*C13 -> 0
A14: CUSTOS VARIÁVEIS TOTAIS | C14: =SUM(C10:C13) -> 0.085 | D14: =SUM(D10:D13) -> 0
A15: LUCRATIVIDADE | C15: 0.15 | D15: =C15*$C$31 -> 0
A17: PARÂMETROS DE CUSTO DO PRODUTO
A18: CUSTO DO MATERIAL | C18: =D18*$C$26/$D$26 -> #DIV/0! | D18: =MATERIAIS!F7 -> 0
B19: AJUSTE DE PROJETO | C19: =D19*$C$26/$D$26 -> #DIV/0! | D19: ='PRODUÇÃO E MONTAGEM'!F9 -> 0
A20: CUSTO CARREGAMENTO E ORGANIZAÇÃO | C20: =D20*$C$26/$D$26 -> #DIV/0! | D20: ='PRODUÇÃO E MONTAGEM'!F14 -> 0
A21: CUSTO DE PRODUÇÃO | C21: =D21*$C$26/$D$26 -> #DIV/0! | D21: ='PRODUÇÃO E MONTAGEM'!F19 -> 0
B22: CUSTO DE MONTAGEM | C22: =D22*$C$26/$D$26 -> #DIV/0! | D22: ='PRODUÇÃO E MONTAGEM'!F31 -> 0
B23: CUSTO ASSISTÊNCIA TÉCNICA | C23: =D23*$C$26/$D$26 -> #DIV/0! | D23: ='PRODUÇÃO E MONTAGEM'!F38 -> 0
A24: CUSTO DO PRODUTO | C24: =D24*$C$26/$D$26 -> #DIV/0! | D24: =SUM(D18:D23) -> 0
B25: OUTROS: | C25: =D25*$C$26/$D$26 -> #DIV/0! | D25: 0
A26: CÁLCULO DOS CUSTOS : TOTAL | C26: 1 | D26: =D24+D25 -> 0
A28: CÁLCULO PREÇO DE VENDA
A29: MARK - UP | C29: =1/(1-(C14+C15)) -> 1.3071895
A31: PREÇO DE VENDA | C31: =($D$26)*C29 -> 0 | D31: 1
A32: IMPOSTO | C32: =D10 -> 0 | D32: =C32*$D$31/$C$31 -> #DIV/0!
A33: CUSTO DO MATERIAL | C33: =D18 -> 0 | D33: =C33*$D$31/$C$31 -> #DIV/0!
A34: CUSTO DO PRODUÇÃO E MONTAGEM | C34: =D21+D22+D20+D23 -> 0 | D34: =C34*$D$31/$C$31 -> #DIV/0!
A35: CUSTO MAT. + PROCESSO + IMPOSTO | C35: =C33+C34+D10 -> 0 | D35: =C35*$D$31/$C$31 -> #DIV/0!
A36: LUCRATIVIDADE | C36: =D15 -> 0 | D36: =C36*$D$31/$C$31 -> #DIV/0!
A38: PREÇO DE VENDA X RELAÇÃO COM MATERIAL
A39: PREÇO DE VENDA/MATERIAL : | C39: =C31/C33 -> #DIV/0! | D39: =C31 -> 0
A40: ESTUDO MULTIPLICADOR X MATERIAL: | C40: 3 | D40: =C33*C40 -> 0
A41: DIFERENÇA PREÇO DE VENDA E INDICADO: | D41: =D40-C31 -> 0
B45: PLANILHA DE FORMAÇÃO DE PREÇO DE VENDA
C46: ATUALIZAÇÃO DA PLANILHA: | D46: =D2 -> 10.01.20
B48: CLIENTE: | C48: =C4 -> 0
B49: PRODUTO: | C49: =C5 -> 0
...
